Workbook

Sheet Summary
A1: ChainLab - Official normalised 40/40/20 MinScore (cost/kg, delivery grain; lower = better). Averages are over SCORED deliveries - unserved deliveries are listed in Unassigned, not silently dropped.
A3: Metric | B3: Normal | C3: PrimaryHubDown | D3: AirCapacityReduced
A4: Average MinScore (scored deliveries) | B4: =AVERAGE(DeliveryScores!$M$2:$M$166) | C4: =AVERAGE(DeliveryScores!$M$167:$M$312) | D4: =AVERAGE(DeliveryScores!$M$313:$M$465)
A5: Median | B5: =MEDIAN(DeliveryScores!$M$2:$M$166) | C5: =MEDIAN(DeliveryScores!$M$167:$M$312) | D5: =MEDIAN(DeliveryScores!$M$313:$M$465)
A6: Std dev | B6: =STDEV(DeliveryScores!$M$2:$M$166) | C6: =STDEV(DeliveryScores!$M$167:$M$312) | D6: =STDEV(DeliveryScores!$M$313:$M$465)
A7: Best (min) | B7: =MIN(DeliveryScores!$M$2:$M$166) | C7: =MIN(DeliveryScores!$M$167:$M$312) | D7: =MIN(DeliveryScores!$M$313:$M$465)
A8: Worst (max) | B8: =MAX(DeliveryScores!$M$2:$M$166) | C8: =MAX(DeliveryScores!$M$167:$M$312) | D8: =MAX(DeliveryScores!$M$313:$M$465)
A9: Shipments routed / universe | B9: 97 / 132 | C9: 89 / 132 | D9: 93 / 132
A10: Deliveries scored / total | B10: 165 / 225 | C10: 146 / 225 | D10: 153 / 225
A11: Multi-week routes selected | B11: 28 | C11: 28 | D11: 24
A12: Unassigned shipments (see Unassigned) | B12: 35 | C12: 43 | D12: 39
A14: BASELINE (primary planned lanes, same solver & normalisation)
A15: Baseline average (Normal) | B15: =AVERAGE(BaselineScores!$M$2:$M$127)
A16: Baseline Q1 - excellent threshold | B16: =QUARTILE(BaselineScores!$M$2:$M$127,1)
A17: Baseline Q3 - weak warning threshold | B17: =QUARTILE(BaselineScores!$M$2:$M$127,3)
A18: Beats baseline? | B18: =IF($B$4<$B$15,"YES - average below baseline","NO")
A19: Excellent (at/below baseline Q1)? | B19: =IF($B$4<=$B$16,"YES - at/below Q1","NO - above Q1")
A20: Weak warning (above baseline Q3)? | B20: =IF($B$4>$B$17,"FLAG - above Q3","OK - not above Q3")
A21: Same-population check (common deliveries) | B21: opt 0.1417 vs baseline 0.1699 on 126 deliveries served by both
A22: Baseline under disruption: no primary planned lanes exist in PrimaryHubDown / AirCapacityReduced - the optimiser finds alternatives (see scenario columns); baseline is reported as unavailable, not zero.
A24: Tradeoff explanation: see Assumptions sheet.

Sheet Assumptions
A1: ChainLab - Official MinScore: Assumptions & Normalisation Bounds
A3: Objective (graded MinScore) | B3: Normalised 40/40/20 MinScore per DELIVERY: 0.4*norm(BaseLeadTimeDays) + 0.4*norm(CostPerKG) + 0.2*norm(RiskScore). Lower is better. Min-max normalisation is a stated modelling assumption (the brief does not specify bounds); bounds shown below and used live by the formulas.
A4: Cost/kg definition | B4: CostPerKG = route BaseCostEUR / individual delivery ChargeableWeight_KG - matches the dataset's own LowestCostPerKG_EUR benchmark definition (verified 225/225). 225 delivery scores share 132 upstream route decisions (one route per internal shipment; capacity charged once per shipment).
A5: Universe | B5: Official score covers the 132 weight-linked internal shipments / 225 deliveries. Internal legs carry no weight (UoM=ST), so cost/kg is undefined for the other 108 shipments - they are routed in the separate proxy (cost/piece) model. Averages are over scored deliveries; unassigned deliveries are listed in Unassigned, never silently dropped.
A6: Scenario layers | B6: Route scenario (Normal/PrimaryHubDown/AirCapacityReduced) filters Route_Options only. Hub disruption is a per-hub attribute in Hub_Constraints; the two DisruptionScenario columns are never matched to each other.
A7: Handling capability | B7: Cold chain + hazard class via dedicated hub booleans; BOTH origin and destination hubs must qualify (stated assumption).
A8: Capacity model | B8: *_pct fields are decimal fractions. remaining = weekly*(max_util*(1-reduction)) - current_load. bottleneck = min(route cap, origin remaining, dest remaining); bottleneck<=0 rejected. WeeklyFootprint = min(Qty, bottleneck) charged identically to route + both hubs per ship-week. Planning horizon: WeeksRequired > 12 throughput weeks -> capacity escalation, never a normal solution. Approximation: footprint charged in ship week (full weekly-flow f[s,r,w] is the documented next step).
A9: Baseline | B9: Primary planned lanes (IsPrimary=Yes) run through the SAME capacity-constrained solver, scored at the same delivery grain with the same normalisation. Q1/Q3 thresholds come from the baseline delivery-score distribution (per Hackathon_Guide). No primary lanes exist under the disruption scenarios - reported as such, not as a zero score.
A10: Solver | B10: Binary PuLP/CBC model; one route or explicit unassigned slack per shipment (never an infeasible model).
A12: Normalisation bounds (min-max, fixed across scenarios)
A13: Lead (days) | B13: 1 | C13: 12
A14: Cost/kg (EUR) | B14: 0.060878963 | C14: 806
A15: Risk | B15: 0.6 | C15: 4.7
A17: Tradeoff explanation (lead time vs cost/kg vs risk)
A18: Lead time and cost/kg carry equal 40% weights: the model only accepts a slower route when its cost/kg saving is at least proportional, and vice versa; risk (20%) breaks ties toward robust lanes. In practice light-weight deliveries have high cost/kg, so their shipments prefer cheap road/sea lanes unless lead time dominates; heavy deliveries dilute cost/kg and take faster lanes. Under PrimaryHubDown / AirCapacityReduced the candidate pool degrades, so the optimiser trades a small score increase for feasible lower-risk alternates instead of unavailable primaries. Handling rules remove non-compliant hubs before scoring; capacity and the 12-week horizon act as hard constraints, so no score wins by violating feasibility.

Sheet DeliveryScores
A1: scenario | B1: DeliveryNo | C1: ShipmentID | D1: RouteOptionID | E1: ChargeableWeight_KG | F1: BaseLeadTimeDays | G1: BaseCostEUR | H1: CostPerKG | I1: RiskScore | J1: n_lead | K1: n_cost | L1: n_risk | M1: DeliveryMinScore
A2: Normal | B2: DEL_CX | C2: SIM-00001 | D2: RO-03601 | E2: 4 | F2: 2 | G2: 497 | H2: =G2/E2 | I2: 1.2 | J2: =(F2-Assumptions!$B$13)/(Assumptions!$C$13-Assumptions!$B$13) | K2: =(H2-Assumptions!$B$14)/(Assumptions!$C$14-Assumptions!$B$14) | L2: =(I2-Assumptions!$B$15)/(Assumptions!$C$15-Assumptions!$B$15) | M2: =0.4*J2+0.4*K2+0.2*L2
A3: Normal | B3: DEL_GH | C3: SIM-00001 | D3: RO-03601 | E3: 1 | F3: 2 | G3: 497 | H3: =G3/E3 | I3: 1.2 | J3: =(F3-Assumptions!$B$13)/(Assumptions!$C$13-Assumptions!$B$13) | K3: =(H3-Assumptions!$B$14)/(Assumptions!$C$14-Assumptions!$B$14) | L3: =(I3-Assumptions!$B$15)/(Assumptions!$C$15-Assumptions!$B$15) | M3: =0.4*J3+0.4*K3+0.2*L3
A4: Normal | B4: DEL_CO | C4: SIM-00002 | D4: RO-03602 | E4: 1063.5 | F4: 4 | G4: 249 | H4: =G4/E4 | I4: 1.8 | J4: =(F4-Assumptions!$B$13)/(Assumptions!$C$13-Assumptions!$B$13) | K4: =(H4-Assumptions!$B$14)/(Assumptions!$C$14-Assumptions!$B$14) | L4: =(I4-Assumptions!$B$15)/(Assumptions!$C$15-Assumptions!$B$15) | M4: =0.4*J4+0.4*K4+0.2*L4
A5: Normal | B5: DEL_GU | C5: SIM-00002 | D5: RO-03602 | E5: 36 | F5: 4 | G5: 249 | H5: =G5/E5 | I5: 1.8 | J5: =(F5-Assumptions!$B$13)/(Assumptions!$C$13-Assumptions!$B$13) | K5: =(H5-Assumptions!$B$14)/(Assumptions!$C$14-Assumptions!$B$14) | L5: =(I5-Assumptions!$B$15)/(Assumptions!$C$15-Assumptions!$B$15) | M5: =0.4*J5+0.4*K5+0.2*L5
A6: Normal | B6: DEL_DI | C6: SIM-00003 | D6: RO-00514 | E6: 2113.5 | F6: 3 | G6: 712 | H6: =G6/E6 | I6: 1.5 | J6: =(F6-Assumptions!$B$13)/(Assumptions!$C$13-Assumptions!$B$13) | K6: =(H6-Assumptions!$B$14)/(Assumptions!$C$14-Assumptions!$B$14) | L6: =(I6-Assumptions!$B$15)/(Assumptions!$C$15-Assumptions!$B$15) | M6: =0.4*J6+0.4*K6+0.2*L6
A7: Normal | B7: DEL_GW | C7: SIM-00003 | D7: RO-00514 | E7: 4.5 | F7: 3 | G7: 712 | H7: =G7/E7 | I7: 1.5 | J7: =(F7-Assumptions!$B$13)/(Assumptions!$C$13-Assumptions!$B$13) | K7: =(H7-Assumptions!$B$14)/(Assumptions!$C$14-Assumptions!$B$14) | L7: =(I7-Assumptions!$B$15)/(Assumptions!$C$15-Assumptions!$B$15) | M7: =0.4*J7+0.4*K7+0.2*L7
A8: Normal | B8: DEL_F | C8: SIM-00004 | D8: RO-00049 | E8: 208 | F8: 4 | G8: 588 | H8: =G8/E8 | I8: 1.5 | J8: =(F8-Assumptions!$B$13)/(Assumptions!$C$13-Assumptions!$B$13) | K8: =(H8-Assumptions!$B$14)/(Assumptions!$C$14-Assumptions!$B$14) | L8: =(I8-Assumptions!$B$15)/(Assumptions!$C$15-Assumptions!$B$15) | M8: =0.4*J8+0.4*K8+0.2*L8
A9: Normal | B9: DEL_BK | C9: SIM-00004 | D9: RO-00049 | E9: 168.5 | F9: 4 | G9: 588 | H9: =G9/E9 | I9: 1.5 | J9: =(F9-Assumptions!$B$13)/(Assumptions!$C$13-Assumptions!$B$13) | K9: =(H9-Assumptions!$B$14)/(Assumptions!$C$14-Assumptions!$B$14) | L9: =(I9-Assumptions!$B$15)/(Assumptions!$C$15-Assumptions!$B$15) | M9: =0.4*J9+0.4*K9+0.2*L9
A10: Normal | B10: DEL_ED | C10: SIM-00004 | D10: RO-00049 | E10: 187 | F10: 4 | G10: 588 | H10: =G10/E10 | I10: 1.5 | J10: =(F10-Assumptions!$B$13)/(Assumptions!$C$13-Assumptions!$B$13) | K10: =(H10-Assumptions!$B$14)/(Assumptions!$C$14-Assumptions!$B$14) | L10: =(I10-Assumptions!$B$15)/(Assumptions!$C$15-Assumptions!$B$15) | M10: =0.4*J10+0.4*K10+0.2*L10
A11: Normal | B11: DEL_BT | C11: SIM-00005 | D11: RO-03605 | E11: 4 | F11: 2 | G11: 545 | H11: =G11/E11 | I11: 1.8 | J11: =(F11-Assumptions!$B$13)/(Assumptions!$C$13-Assumptions!$B$13) | K11: =(H11-Assumptions!$B$14)/(Assumptions!$C$14-Assumptions!$B$14) | L11: =(I11-Assumptions!$B$15)/(Assumptions!$C$15-Assumptions!$B$15) | M11: =0.4*J11+0.4*K11+0.2*L11
A12: Normal | B12: DEL_CE | C12: SIM-00005 | D12: RO-03605 | E12: 1395 | F12: 2 | G12: 545 | H12: =G12/E12 | I12: 1.8 | J12: =(F12-Assumptions!$B$13)/(Assumptions!$C$13-Assumptions!$B$13) | K12: =(H12-Assumptions!$B$14)/(Assumptions!$C$14-Assumptions!$B$14) | L12: =(I12-Assumptions!$B$15)/(Assumptions!$C$15-Assumptions!$B$15) | M12: =0.4*J12+0.4*K12+0.2*L12
A13: Normal | B13: DEL_FN | C13: SIM-00005 | D13: RO-03605 | E13: 518.5 | F13: 2 | G13: 545 | H13: =G13/E13 | I13: 1.8 | J13: =(F13-Assumptions!$B$13)/(Assumptions!$C$13-Assumptions!$B$13) | K13: =(H13-Assumptions!$B$14)/(Assumptions!$C$14-Assumptions!$B$14) | L13: =(I13-Assumptions!$B$15)/(Assumptions!$C$15-Assumptions!$B$15) | M13: =0.4*J13+0.4*K13+0.2*L13
... A465: AirCapacityReduced | B465: DEL_DY | C465: SIM-00240 | D465: RO-03240 | E465: 78 | F465: 5 | G465: 350 | H465: =G465/E465 | I465: 2.5 | J465: =(F465-Assumptions!$B$13)/(Assumptions!$C$13-Assumptions!$B$13) | K465: =(H465-Assumptions!$B$14)/(Assumptions!$C$14-Assumptions!$B$14) | L465: =(I465-Assumptions!$B$15)/(Assumptions!$C$15-Assumptions!$B$15) | M465: =0.4*J465+0.4*K465+0.2*L465

Sheet BaselineScores
A1: scenario | B1: DeliveryNo | C1: ShipmentID | D1: RouteOptionID | E1: ChargeableWeight_KG | F1: BaseLeadTimeDays | G1: BaseCostEUR | H1: CostPerKG | I1: RiskScore | J1: n_lead | K1: n_cost | L1: n_risk | M1: DeliveryMinScore | O1: Baseline = primary planned lanes through the SAME capacity-constrained solver. No primary lanes exist under disruption scenarios.
A2: Normal | B2: DEL_CX | C2: SIM-00001 | D2: RO-03601 | E2: 4 | F2: 2 | G2: 497 | H2: =G2/E2 | I2: 1.2 | J2: =(F2-Assumptions!$B$13)/(Assumptions!$C$13-Assumptions!$B$13) | K2: =(H2-Assumptions!$B$14)/(Assumptions!$C$14-Assumptions!$B$14) | L2: =(I2-Assumptions!$B$15)/(Assumptions!$C$15-Assumptions!$B$15) | M2: =0.4*J2+0.4*K2+0.2*L2
A3: Normal | B3: DEL_GH | C3: SIM-00001 | D3: RO-03601 | E3: 1 | F3: 2 | G3: 497 | H3: =G3/E3 | I3: 1.2 | J3: =(F3-Assumptions!$B$13)/(Assumptions!$C$13-Assumptions!$B$13) | K3: =(H3-Assumptions!$B$14)/(Assumptions!$C$14-Assumptions!$B$14) | L3: =(I3-Assumptions!$B$15)/(Assumptions!$C$15-Assumptions!$B$15) | M3: =0.4*J3+0.4*K3+0.2*L3
A4: Normal | B4: DEL_CO | C4: SIM-00002 | D4: RO-03602 | E4: 1063.5 | F4: 4 | G4: 249 | H4: =G4/E4 | I4: 1.8 | J4: =(F4-Assumptions!$B$13)/(Assumptions!$C$13-Assumptions!$B$13) | K4: =(H4-Assumptions!$B$14)/(Assumptions!$C$14-Assumptions!$B$14) | L4: =(I4-Assumptions!$B$15)/(Assumptions!$C$15-Assumptions!$B$15) | M4: =0.4*J4+0.4*K4+0.2*L4
A5: Normal | B5: DEL_GU | C5: SIM-00002 | D5: RO-03602 | E5: 36 | F5: 4 | G5: 249 | H5: =G5/E5 | I5: 1.8 | J5: =(F5-Assumptions!$B$13)/(Assumptions!$C$13-Assumptions!$B$13) | K5: =(H5-Assumptions!$B$14)/(Assumptions!$C$14-Assumptions!$B$14) | L5: =(I5-Assumptions!$B$15)/(Assumptions!$C$15-Assumptions!$B$15) | M5: =0.4*J5+0.4*K5+0.2*L5
A6: Normal | B6: DEL_DI | C6: SIM-00003 | D6: RO-03603 | E6: 2113.5 | F6: 10 | G6: 181 | H6: =G6/E6 | I6: 2.9 | J6: =(F6-Assumptions!$B$13)/(Assumptions!$C$13-Assumptions!$B$13) | K6: =(H6-Assumptions!$B$14)/(Assumptions!$C$14-Assumptions!$B$14) | L6: =(I6-Assumptions!$B$15)/(Assumptions!$C$15-Assumptions!$B$15) | M6: =0.4*J6+0.4*K6+0.2*L6
A7: Normal | B7: DEL_GW | C7: SIM-00003 | D7: RO-03603 | E7: 4.5 | F7: 10 | G7: 181 | H7: =G7/E7 | I7: 2.9 | J7: =(F7-Assumptions!$B$13)/(Assumptions!$C$13-Assumptions!$B$13) | K7: =(H7-Assumptions!$B$14)/(Assumptions!$C$14-Assumptions!$B$14) | L7: =(I7-Assumptions!$B$15)/(Assumptions!$C$15-Assumptions!$B$15) | M7: =0.4*J7+0.4*K7+0.2*L7
A8: Normal | B8: DEL_F | C8: SIM-00004 | D8: RO-03604 | E8: 208 | F8: 4 | G8: 533 | H8: =G8/E8 | I8: 1.7 | J8: =(F8-Assumptions!$B$13)/(Assumptions!$C$13-Assumptions!$B$13) | K8: =(H8-Assumptions!$B$14)/(Assumptions!$C$14-Assumptions!$B$14) | L8: =(I8-Assumptions!$B$15)/(Assumptions!$C$15-Assumptions!$B$15) | M8: =0.4*J8+0.4*K8+0.2*L8
A9: Normal | B9: DEL_BK | C9: SIM-00004 | D9: RO-03604 | E9: 168.5 | F9: 4 | G9: 533 | H9: =G9/E9 | I9: 1.7 | J9: =(F9-Assumptions!$B$13)/(Assumptions!$C$13-Assumptions!$B$13) | K9: =(H9-Assumptions!$B$14)/(Assumptions!$C$14-Assumptions!$B$14) | L9: =(I9-Assumptions!$B$15)/(Assumptions!$C$15-Assumptions!$B$15) | M9: =0.4*J9+0.4*K9+0.2*L9
A10: Normal | B10: DEL_ED | C10: SIM-00004 | D10: RO-03604 | E10: 187 | F10: 4 | G10: 533 | H10: =G10/E10 | I10: 1.7 | J10: =(F10-Assumptions!$B$13)/(Assumptions!$C$13-Assumptions!$B$13) | K10: =(H10-Assumptions!$B$14)/(Assumptions!$C$14-Assumptions!$B$14) | L10: =(I10-Assumptions!$B$15)/(Assumptions!$C$15-Assumptions!$B$15) | M10: =0.4*J10+0.4*K10+0.2*L10
A11: Normal | B11: DEL_BT | C11: SIM-00005 | D11: RO-03605 | E11: 4 | F11: 2 | G11: 545 | H11: =G11/E11 | I11: 1.8 | J11: =(F11-Assumptions!$B$13)/(Assumptions!$C$13-Assumptions!$B$13) | K11: =(H11-Assumptions!$B$14)/(Assumptions!$C$14-Assumptions!$B$14) | L11: =(I11-Assumptions!$B$15)/(Assumptions!$C$15-Assumptions!$B$15) | M11: =0.4*J11+0.4*K11+0.2*L11
A12: Normal | B12: DEL_CE | C12: SIM-00005 | D12: RO-03605 | E12: 1395 | F12: 2 | G12: 545 | H12: =G12/E12 | I12: 1.8 | J12: =(F12-Assumptions!$B$13)/(Assumptions!$C$13-Assumptions!$B$13) | K12: =(H12-Assumptions!$B$14)/(Assumptions!$C$14-Assumptions!$B$14) | L12: =(I12-Assumptions!$B$15)/(Assumptions!$C$15-Assumptions!$B$15) | M12: =0.4*J12+0.4*K12+0.2*L12
A13: Normal | B13: DEL_FN | C13: SIM-00005 | D13: RO-03605 | E13: 518.5 | F13: 2 | G13: 545 | H13: =G13/E13 | I13: 1.8 | J13: =(F13-Assumptions!$B$13)/(Assumptions!$C$13-Assumptions!$B$13) | K13: =(H13-Assumptions!$B$14)/(Assumptions!$C$14-Assumptions!$B$14) | L13: =(I13-Assumptions!$B$15)/(Assumptions!$C$15-Assumptions!$B$15) | M13: =0.4*J13+0.4*K13+0.2*L13
... A127: Normal | B127: DEL_DY | C127: SIM-00240 | D127: RO-03819 | E127: 78 | F127: 3 | G127: 681 | H127: =G127/E127 | I127: 1.1 | J127: =(F127-Assumptions!$B$13)/(Assumptions!$C$13-Assumptions!$B$13) | K127: =(H127-Assumptions!$B$14)/(Assumptions!$C$14-Assumptions!$B$14) | L127: =(I127-Assumptions!$B$15)/(Assumptions!$C$15-Assumptions!$B$15) | M127: =0.4*J127+0.4*K127+0.2*L127

Sheet RouteDecisions
A1: scenario | B1: ShipmentID | C1: RouteOptionID | D1: FromHub | E1: ToHub | F1: TransportMode | G1: IsPrimary | H1: Qty | I1: WeeksRequired | J1: MultiWeek | K1: BaseLeadTimeDays | L1: EffectiveLeadTimeDays | M1: BaseCostEUR | N1: RiskScore | O1: CO2Kg
A2: Normal | B2: SIM-00001 | C2: RO-03601 | D2: FE_LOC_001 | E2: SIFO_LOC_001 | F2: Air | G2: Yes | H2: 850 | I2: 1 | J2: FALSE | K2: 2 | L2: 2 | M2: 497 | N2: 1.2 | O2: 196
A3: Normal | B3: SIM-00002 | C3: RO-03602 | D3: SIFO_LOC_006 | E3: BE_LOC_008 | F3: Road | G3: Yes | H3: 200 | I3: 1 | J3: FALSE | K3: 4 | L3: 4 | M3: 249 | N3: 1.8 | O3: 112
A4: Normal | B4: SIM-00003 | C4: RO-00514 | D4: BE_ALT_36 | E4: OSAT_ALT_36 | F4: Ocean | G4: No | H4: 300 | I4: 1 | J4: FALSE | K4: 3 | L4: 3 | M4: 712 | N4: 1.5 | O4: 166
A5: Normal | B5: SIM-00004 | C5: RO-00049 | D5: OSAT_ALT_05 | E5: BE_ALT_05 | F5: Air | G5: No | H5: 3400 | I5: 1 | J5: FALSE | K5: 4 | L5: 4 | M5: 588 | N5: 1.5 | O5: 208
A6: Normal | B6: SIM-00005 | C6: RO-03605 | D6: BE_LOC_021 | E6: SIFO_LOC_029 | F6: Air | G6: Yes | H6: 500 | I6: 1 | J6: FALSE | K6: 2 | L6: 2 | M6: 545 | N6: 1.8 | O6: 212
A7: Normal | B7: SIM-00010 | C7: RO-01108 | D7: SIFO_ALT_78 | E7: OSAT_ALT_78 | F7: Road | G7: No | H7: 30000 | I7: 4 | J7: TRUE | K7: 5 | L7: 26 | M7: 292 | N7: 2.3 | O7: 126
A8: Normal | B8: SIM-00012 | C8: RO-01486 | D8: SIFO_ALT_10 | E8: BE_ALT_10 | F8: Courier | G8: No | H8: 36000 | I8: 8 | J8: TRUE | K8: 1 | L8: 50 | M8: 712 | N8: 1.5 | O8: 170
A9: Normal | B9: SIM-00016 | C9: RO-01912 | D9: SIFO_ALT_40 | E9: FE_ALT_40 | F9: Courier | G9: No | H9: 1600 | I9: 1 | J9: FALSE | K9: 4 | L9: 4 | M9: 328 | N9: 2.3 | O9: 104
A10: Normal | B10: SIM-00018 | C10: RO-00265 | D10: BE_ALT_21 | E10: BE_ALT_21 | F10: Road | G10: No | H10: 9000 | I10: 2 | J10: TRUE | K10: 2 | L10: 9 | M10: 588 | N10: 1.5 | O10: 196
A11: Normal | B11: SIM-00019 | C11: RO-03619 | D11: OSAT_LOC_011 | E11: OSAT_LOC_047 | F11: Courier | G11: Yes | H11: 450 | I11: 1 | J11: FALSE | K11: 3 | L11: 3 | M11: 657 | N11: 0.8 | O11: 170
A12: Normal | B12: SIM-00021 | C12: RO-00541 | D12: FE_ALT_37 | E12: SIFO_ALT_37 | F12: Air | G12: No | H12: 300 | I12: 1 | J12: FALSE | K12: 2 | L12: 2 | M12: 552 | N12: 1.5 | O12: 212
A13: Normal | B13: SIM-00022 | C13: RO-03622 | D13: SIFO_LOC_026 | E13: BE_LOC_068 | F13: Road | G13: Yes | H13: 400 | I13: 1 | J13: FALSE | K13: 4 | L13: 4 | M13: 273 | N13: 2 | O13: 128
... A280: AirCapacityReduced | B280: SIM-00240 | C280: RO-03240 | D280: SIFO_ALT_42 | E280: OSAT_ALT_46 | F280: Courier | G280: No | H280: 600 | I280: 1 | J280: FALSE | K280: 5 | L280: 5 | M280: 350 | N280: 2.5 | O280: 110

Sheet Unassigned
A1: scenario | B1: ShipmentID | C1: Reason | D1: LinkedDeliveries | E1: BestAvailableWeeks | F1: BestAvailableRoute | G1: RecommendedAction
A2: Normal | B2: SIM-00007 | C2: handling_infeasible | D2: 7 | G2: No handling-compatible hub - source alternate hub / supplier exception
A3: Normal | B3: SIM-00009 | C3: capacity_escalation | D3: 1 | E3: 14 | F3: RO-03609 | G3: Exceeds quarter horizon - split order across periods or add capacity
A4: Normal | B4: SIM-00013 | C4: capacity_escalation | D4: 1 | E4: 16 | F4: RO-03613 | G4: Exceeds quarter horizon - split order across periods or add capacity
A5: Normal | B5: SIM-00014 | C5: capacity_escalation | D5: 2 | E5: 32 | F5: RO-03614 | G5: Exceeds quarter horizon - split order across periods or add capacity
A6: Normal | B6: SIM-00015 | C6: handling_infeasible | D6: 5 | G6: No handling-compatible hub - source alternate hub / supplier exception
A7: Normal | B7: SIM-00035 | C7: handling_infeasible | D7: 1 | G7: No handling-compatible hub - source alternate hub / supplier exception
A8: Normal | B8: SIM-00042 | C8: capacity_escalation | D8: 1 | E8: 13 | F8: RO-03642 | G8: Exceeds quarter horizon - split order across periods or add capacity
A9: Normal | B9: SIM-00047 | C9: handling_infeasible | D9: 1 | G9: No handling-compatible hub - source alternate hub / supplier exception
A10: Normal | B10: SIM-00066 | C10: handling_infeasible | D10: 1 | G10: No handling-compatible hub - source alternate hub / supplier exception
A11: Normal | B11: SIM-00071 | C11: handling_infeasible | D11: 1 | G11: No handling-compatible hub - source alternate hub / supplier exception
A12: Normal | B12: SIM-00083 | C12: capacity_escalation | D12: 2 | E12: 18 | F12: RO-03683 | G12: Exceeds quarter horizon - split order across periods or add capacity
A13: Normal | B13: SIM-00086 | C13: capacity_escalation | D13: 1 | E13: 73 | F13: RO-00202 | G13: Exceeds quarter horizon - split order across periods or add capacity
A14: Normal | B14: SIM-00107 | C14: handling_infeasible | D14: 1 | G14: No handling-compatible hub - source alternate hub / supplier exception
A15: Normal | B15: SIM-00111 | C15: handling_infeasible | D15: 3 | G15: No handling-compatible hub - source alternate hub / supplier exception
A16: Normal | B16: SIM-00126 | C16: handling_infeasible | D16: 1 | G16: No handling-compatible hub - source alternate hub / supplier exception
A17: Normal | B17: SIM-00131 | C17: handling_infeasible | D17: 1 | G17: No handling-compatible hub - source alternate hub / supplier exception
A18: Normal | B18: SIM-00133 | C18: capacity_escalation | D18: 2 | E18: 25 | F18: RO-03613 | G18: Exceeds quarter horizon - split order across periods or add capacity
A19: Normal | B19: SIM-00135 | C19: handling_infeasible | D19: 1 | G19: No handling-compatible hub - source alternate hub / supplier exception
A20: Normal | B20: SIM-00136 | C20: capacity_escalation | D20: 2 | E20: 41 | F20: RO-00832 | G20: Exceeds quarter horizon - split order across periods or add capacity
A21: Normal | B21: SIM-00147 | C21: handling_infeasible | D21: 1 | G21: No handling-compatible hub - source alternate hub / supplier exception
A22: Normal | B22: SIM-00151 | C22: handling_infeasible | D22: 1 | G22: No handling-compatible hub - source alternate hub / supplier exception
A23: Normal | B23: SIM-00160 | C23: capacity_escalation | D23: 1 | E23: 89 | F23: RO-00838 | G23: Exceeds quarter horizon - split order across periods or add capacity
A24: Normal | B24: SIM-00161 | C24: capacity_escalation | D24: 1 | E24: 20 | F24: RO-03681 | G24: Exceeds quarter horizon - split order across periods or add capacity
A25: Normal | B25: SIM-00166 | C25: handling_infeasible | D25: 1 | G25: No handling-compatible hub - source alternate hub / supplier exception
A26: Normal | B26: SIM-00171 | C26: handling_infeasible | D26: 1 | G26: No handling-compatible hub - source alternate hub / supplier exception
A27: Normal | B27: SIM-00172 | C27: capacity_escalation | D27: 2 | E27: 28 | F27: RO-02686 | G27: Exceeds quarter horizon - split order across periods or add capacity
A28: Normal | B28: SIM-00179 | C28: capacity_escalation | D28: 1 | E28: 13 | F28: RO-00643 | G28: Exceeds quarter horizon - split order across periods or add capacity
A29: Normal | B29: SIM-00191 | C29: handling_infeasible | D29: 1 | G29: No handling-compatible hub - source alternate hub / supplier exception
A30: Normal | B30: SIM-00204 | C30: capacity_escalation | D30: 2 | E30: 30 | F30: RO-03049 | G30: Exceeds quarter horizon - split order across periods or add capacity
A31: Normal | B31: SIM-00207 | C31: handling_infeasible | D31: 1 | G31: No handling-compatible hub - source alternate hub / supplier exception
A32: Normal | B32: SIM-00208 | C32: capacity_escalation | D32: 1 | E32: 15 | F32: RO-02035 | G32: Exceeds quarter horizon - split order across periods or add capacity
A33: Normal | B33: SIM-00213 | C33: capacity_escalation | D33: 4 | E33: 17 | F33: RO-03691 | G33: Exceeds quarter horizon - split order across periods or add capacity
A34: Normal | B34: SIM-00214 | C34: capacity_escalation | D34: 1 | E34: 24 | F34: RO-03793 | G34: Exceeds quarter horizon - split order across periods or add capacity
A35: Normal | B35: SIM-00221 | C35: handling_infeasible | D35: 5 | G35: No handling-compatible hub - source alternate hub / supplier exception
A36: Normal | B36: SIM-00235 | C36: handling_infeasible | D36: 1 | G36: No handling-compatible hub - source alternate hub / supplier exception
A37: PrimaryHubDown | B37: SIM-00007 | C37: handling_infeasible | D37: 7 | G37: No handling-compatible hub - source alternate hub / supplier exception
A38: PrimaryHubDown | B38: SIM-00009 | C38: capacity_escalation | D38: 1 | E38: 18 | F38: RO-01214 | G38: Exceeds quarter horizon - split order across periods or add capacity
A39: PrimaryHubDown | B39: SIM-00013 | C39: capacity_escalation | D39: 1 | E39: 21 | F39: RO-02705 | G39: Exceeds quarter horizon - split order across periods or add capacity
A40: PrimaryHubDown | B40: SIM-00014 | C40: capacity_escalation | D40: 2 | E40: 81 | F40: RO-01280 | G40: Exceeds quarter horizon - split order across periods or add capacity
...
